<?xml version="1.0"?>
<robot xmlns:xacro="http://www.ros.org/wiki/xacro" name="ur_robot">
    
    <!--xacro-->
    <xacro:macro name="cylinder_inertial" params="radius length mass *origin">
        <inertial>
            <mass value="${mass}" />
            <xacro:insert_block name="origin" />
            <inertia ixx="${0.0833333 * mass * (3 * radius * radius + length * length)}" ixy="0.0" ixz="0.0"
                iyy="${0.0833333 * mass * (3 * radius * radius + length * length)}" iyz="0.0"
                izz="${0.5 * mass * radius * radius}" />
        </inertial>
    </xacro:macro>

    <!--include-->
    <xacro:include filename="$(find ur_bot)/urdf/urbot.gazebo"/>

    <!-- Inertia parameters -->
    <xacro:property name="base_mass" value="4.0" />
    <xacro:property name="shoulder_mass" value="3.7000" />
    <xacro:property name="upper_arm_mass" value="8.3930" />
    <xacro:property name="forearm_mass" value="2.2750" />
    <xacro:property name="wrist_1_mass" value="1.2190" />
    <xacro:property name="wrist_2_mass" value="1.2190" />
    <xacro:property name="wrist_3_mass" value="0.1879" />

    <xacro:property name="shoulder_cog" value="0.0 0.00193 -0.02561" />
    <xacro:property name="upper_arm_cog" value="0.0 -0.024201 0.2125" />
    <xacro:property name="forearm_cog" value="0.0 0.0265 0.11993" />
    <xacro:property name="wrist_1_cog" value="0.0 0.110949 0.01634" />
    <xacro:property name="wrist_2_cog" value="0.0 0.0018 0.11099" />
    <xacro:property name="wrist_3_cog" value="0.0 0.001159 0.0" />

    <!--DH params-->
    <xacro:property name="d1" value="0.089159" />
    <xacro:property name="a2" value="-0.42500" />
    <xacro:property name="a3" value="-0.39225" />
    <xacro:property name="d4" value="0.10915" />
    <xacro:property name="d5" value="0.09465" />
    <xacro:property name="d6" value="0.0823" />

    <!--Robot params-->
    <!-- Arbitrary offsets for shoulder/elbow joints -->
    <xacro:property name="shoulder_offset" value="0.13585" />  <!-- measured from model -->
    <xacro:property name="elbow_offset" value="-0.1197" /> <!-- measured from model -->
    <!-- link lengths used in model -->
    <xacro:property name="shoulder_height" value="${d1}" />
    <xacro:property name="upper_arm_length" value="${-a2}" />
    <xacro:property name="forearm_length" value="${-a3}" />
    <xacro:property name="wrist_1_length" value="${d4 - elbow_offset - shoulder_offset}" />
    <xacro:property name="wrist_2_length" value="${d5}" />
    <xacro:property name="wrist_3_length" value="${d6}" />
    <xacro:property name="shoulder_radius" value="0.060" />   <!-- manually measured -->
    <xacro:property name="upper_arm_radius" value="0.054" />  <!-- manually measured -->
    <xacro:property name="elbow_radius" value="0.060" />      <!-- manually measured -->
    <xacro:property name="forearm_radius" value="0.040" />    <!-- manually measured -->
    <xacro:property name="wrist_radius" value="0.045" />      <!-- manually measured -->

    <!--model-->
    <link name="base_link" >
        <visual>
            <geometry>
                <mesh filename="package://ur_bot/meshes/visual/base.dae" />
            </geometry>
            <material name="LightGrey">
                <color rgba="0.7 0.7 0.7 1.0"/>
            </material>
        </visual>
        <collision>
            <geometry>
                <mesh filename="package://ur_bot/meshes/collision/base.stl" />
            </geometry>
        </collision>
        <xacro:cylinder_inertial radius="0.06" length="0.05" mass="${base_mass}">
            <origin xyz="0.0 0.0 0.0" rpy="0 0 0" />
        </xacro:cylinder_inertial>
    </link>

    <joint name="shoulder_pan_joint" type="revolute">
      <parent link="base_link" />
      <child link = "shoulder_link" />
      <origin xyz="0.0 0.0 ${shoulder_height}" rpy="0.0 0.0 0.0" />
      <axis xyz="0 0 1" />
      <dynamics damping="0.0" friction="0.0"/>
			<limit lower="-3.14" upper="3.14" effort="100" velocity="0.5"/>
    </joint>


    <link name="shoulder_link">
        <visual>
            <geometry>
                <mesh filename="package://ur_bot/meshes/visual/shoulder.dae" />
            </geometry>
            <material name="LightGrey">
                <color rgba="0.7 0.7 0.7 1.0"/>
            </material>
        </visual>
        <collision>
            <geometry>
                <mesh filename="package://ur_bot/meshes/collision/shoulder.stl" />
            </geometry>
        </collision>
        <xacro:cylinder_inertial radius="0.06" length="0.15" mass="${shoulder_mass}">
            <origin xyz="0.0 0.0 0.0" rpy="0 0 0" />
        </xacro:cylinder_inertial>
    </link>

    <joint name="shoulder_lift_joint" type="revolute">
      <parent link="shoulder_link" />
      <child link = "upper_arm_link" />
      <origin xyz="0.0 ${shoulder_offset} 0.0" rpy="0.0 0 0.0" />
      <axis xyz="0 1 0" />
      <dynamics damping="0.0" friction="0.0"/>
			<limit lower="-3.14" upper="3.14" effort="100" velocity="0.5"/>
    </joint>

    <link name="upper_arm_link">
        <visual>
            <geometry>
                <mesh filename="package://ur_bot/meshes/visual/upperarm.dae" />
            </geometry>
            <material name="LightGrey">
                <color rgba="0.7 0.7 0.7 1.0"/>
            </material>
        </visual>
        <collision>
            <geometry>
                <mesh filename="package://ur_bot/meshes/collision/upperarm.stl" />
            </geometry>
        </collision>
        <xacro:cylinder_inertial radius="0.06" length="0.56" mass="${upper_arm_mass}">
            <origin xyz="0.0 0.0 0.28" rpy="0 0 0" />
        </xacro:cylinder_inertial>
    </link>

    <joint name="elbow_joint" type="revolute">
      <parent link="upper_arm_link" />
      <child link = "forearm_link" />
      <origin xyz="0.0 ${elbow_offset} ${upper_arm_length}" rpy="0.0 0.0 0.0" />
      <axis xyz="0 1 0" />
      <dynamics damping="0.0" friction="0.0"/>
			<limit lower="-3.14" upper="3.14" effort="100" velocity="0.5"/>
    </joint>


    <link name="forearm_link">
        <visual>
        <geometry>
            <mesh filename="package://ur_bot/meshes/visual/forearm.dae" />
        </geometry>
        <material name="LightGrey">
            <color rgba="0.7 0.7 0.7 1.0"/>
        </material>
        </visual>
        <collision>
        <geometry>
            <mesh filename="package://ur_bot/meshes/collision/forearm.stl" />
        </geometry>
        </collision>
        <xacro:cylinder_inertial radius="0.06" length="${-a3}" mass="${forearm_mass}">
        <origin xyz="0.0 0.0 ${-a3/2}" rpy="0 0 0" />
        </xacro:cylinder_inertial>
    </link>

    <joint name="wrist_1_joint" type="revolute">
      <parent link="forearm_link" />
      <child link = "wrist_1_link" />
      <origin xyz="0.0 0.0 ${forearm_length}" rpy="0.0 0 0.0" />
      <axis xyz="0 1 0" />
      <dynamics damping="0.0" friction="0.0"/>
			<limit lower="-3.14" upper="3.14" effort="100" velocity="0.5"/>
    </joint>


    <link name="wrist_1_link">
      <visual>
        <geometry>
          <mesh filename="package://ur_bot/meshes/visual/wrist1.dae" />
        </geometry>
        <material name="LightGrey">
          <color rgba="0.7 0.7 0.7 1.0"/>
        </material>
      </visual>
      <collision>
        <geometry>
          <mesh filename="package://ur_bot/meshes/collision/wrist1.stl" />
        </geometry>
      </collision>
      <xacro:cylinder_inertial radius="0.06" length="0.12" mass="${wrist_1_mass}">
        <origin xyz="0.0 ${wrist_1_length} 0.0" rpy="0 0 0" />
      </xacro:cylinder_inertial>
    </link>


    <joint name="wrist_2_joint" type="revolute">
      <parent link="wrist_1_link" />
      <child link = "wrist_2_link" />
      <origin xyz="0.0 ${wrist_1_length} 0.0" rpy="0.0 0.0 0.0" />
      <axis xyz="0 0 1" />
      <dynamics damping="0.0" friction="0.0"/>
			<limit lower="-3.14" upper="3.14" effort="100" velocity="0.5"/>
    </joint>

    <link name="wrist_2_link">
      <visual>
        <geometry>
          <mesh filename="package://ur_bot/meshes/visual/wrist2.dae" />
        </geometry>
        <material name="LightGrey">
          <color rgba="0.7 0.7 0.7 1.0"/>
        </material>
      </visual>
      <collision>
        <geometry>
          <mesh filename="package://ur_bot/meshes/collision/wrist2.stl" />
        </geometry>
      </collision>
      <xacro:cylinder_inertial radius="0.06" length="0.12" mass="${wrist_2_mass}">
        <origin xyz="0.0 0.0 ${wrist_2_length}" rpy="0 0 0" />
      </xacro:cylinder_inertial>
    </link>


    <joint name="wrist_3_joint" type="revolute">
      <parent link="wrist_2_link" />
      <child link = "wrist_3_link" />
      <origin xyz="0.0 0.0 ${wrist_2_length}" rpy="0.0 0.0 0.0" />
      <axis xyz="0 1 0" />
      <dynamics damping="0.0" friction="0.0"/>
			<limit lower="-3.14" upper="3.14" effort="100" velocity="0.5"/>
    </joint>

    <link name="wrist_3_link">
      <visual>
        <geometry>
          <mesh filename="package://ur_bot/meshes/visual/wrist3.dae" />
        </geometry>
        <material name="LightGrey">
          <color rgba="0.7 0.7 0.7 1.0"/>
        </material>
      </visual>
      <collision>
        <geometry>
          <mesh filename="package://ur_bot/meshes/collision/wrist3.stl" />
        </geometry>
      </collision>
      <xacro:cylinder_inertial radius="0.0375" length="0.0345" mass="${wrist_3_mass}">
        <origin xyz="0.0 ${wrist_3_length - 0.0345/2} 0.0" rpy="${pi/2} 0 0" />
      </xacro:cylinder_inertial>
    </link>

    <joint name="ee_fixed_joint" type="fixed">
      <parent link="wrist_3_link" />
      <child link = "ee_link" />
      <origin xyz="0.0 ${wrist_3_length} 0.0" rpy="0.0 0.0 ${pi/2.0}" />
    </joint>


    <link name="ee_link">
      <collision>
        <geometry>
          <box size="0.01 0.01 0.01"/>
        </geometry>
        <origin rpy="0 0 0" xyz="-0.01 0 0"/>
      </collision>
    </link>

    <link name="world"/>
    <joint name="fixed" type="fixed">
      <origin xyz="0 0 0" rpy="0 0 ${-pi}"/>
      <parent link="world"/>
      <child link="base_link"/>
    </joint>

</robot>
